import catchAsync from './../utils/catchAsync.js';
import AppError from './../utils/appError.js';

export const getAll = (Model) =>
  catchAsync(async (req, res, next) => {
    const doc = await Model.find();
    res
      .status(200)
      .json({ status: 'success', data: { length: doc.length, doc } });
  });

export const getOne = (Model) =>
  catchAsync(async (req, res, next) => {
    const doc = await Model.findById(req.params.id);

    if (!doc) {
      return next(new AppError('No document found with that ID', 404));
    }

    res.status(200).json({
      status: 'success',
      data: {
        doc,
      },
    });
  });

export const createOne = (Model) =>
  catchAsync(async (req, res, next) => {
    const doc = await Model.create(req.body);

    res.status(201).json({
      status: 'success',
      data: {
        data: doc,
      },
    });
  });

export const updateOne = (Model) =>
  catchAsync(async (req, res, next) => {
    const doc = await Model.findByIdAndUpdate(req.params.id, req.body, {
      new: true,
      runValidators: true,
    });

    if (!doc) {
      return next(new AppError('No document found with that ID', 404));
    }

    res.status(200).json({
      status: 'success',
      data: {
        data: doc,
      },
    });
  });

export const deleteOne = (Model) =>
  catchAsync(async (req, res, next) => {
    const doc = await Model.findByIdAndDelete(req.params.id);

    if (!doc) {
      return next(new AppError('No document found with that ID', 404));
    }
    res.status(204).json({ status: 'success', data: null });
  });
